Workbook

Sheet YVAM Annual Estimate@25-17
A2: YVAM1500--1300 KW@25C/17C Texas
E3: 1 | G3: 0.9 | I3: 0.8 | K3: 0.7 | M3: 0.65 | O3: 0.6 | Q3: 0.55 | S3: 0.5 | U3: 0.45 | W3: 0.4 | Y3: 0.35 | AA3: 0.3 | AC3: 0.25 | AE3: 0.2 | AG3: 0.15
A4: Bin Temp [F] | B4: Average Ambient[F] | C4: Average Ambient[C] | D4: Total Operating Hours | E4: kW | F4: Annual kW | G4: kW | H4: Annual kWh | I4: kW | J4: Annual kWh | K4: kW | L4: Annual kWh | M4: kW | N4: Annual kWh | O4: kW | P4: Annual kWh | Q4: kW | R4: Annual kWh | S4: kW | T4: Annual kWh | U4: kW | V4: Annual kWh | W4: kW | X4: Annual kWh | Y4: kW | Z4: Annual kWh | AA4: kW | AB4: Annual kWh | AC4: kW | AD4: Annual kWh | AE4: kW | AF4: Annual kWh | AG4: kW | AH4: Annual kWh
A5: 110 - 115 | B5: =B6+5 -> 112.5 | C5: 44.722222 | D5: 1 | E5: ='[1]YVAM chiller load reference'!D3 -> 380.4 | F5: =E5*Table1343[[#This Row],[Total Operating Hours]] -> 380.4 | G5: ='[1]YVAM chiller load reference'!L3 -> 350.3 | H5: =G5*Table1343[[#This Row],[Total Operating Hours]] -> 350.3 | I5: ='[1]YVAM chiller load reference'!S3 -> 312 | J5: =I5*Table1343[[#This Row],[Total Operating Hours]] -> 312 | K5: ='[1]YVAM chiller load reference'!Z3 -> 274.6 | L5: =K5*Table1343[[#This Row],[Total Operating Hours]] -> 274.6 | M5: ='[1]YVAM chiller load reference'!BD3 -> 259.5 | N5: =M5*Table1343[[#This Row],[Total Operating Hours]] -> 259.5 | O5: ='[1]YVAM chiller load reference'!AG3 -> 240.2 | P5: =O5*Table1343[[#This Row],[Total Operating Hours]] -> 240.2 | Q5: ='[1]YVAM chiller load reference'!BR3 -> 240.5 | R5: =Q5*Table1343[[#This Row],[Total Operating Hours]] -> 240.5 | S5: ='[1]YVAM chiller load reference'!AN3 -> 208.9 | T5: =S5*Table1343[[#This Row],[Total Operating Hours]] -> 208.9 | U5: ='[1]YVAM chiller load reference'!CF3 -> 0 | V5: =U5*Table1343[[#This Row],[Total Operating Hours]] -> 0 | W5: ='[1]YVAM chiller load reference'!AU3 -> 181.6 | X5: =W5*Table1343[[#This Row],[Total Operating Hours]] -> 181.6 | Y5: ='[1]YVAM chiller load reference'!CT3 -> 0 | Z5: =Y5*Table1343[[#This Row],[Total Operating Hours]] -> 0 | AA5: ='[1]YVAM chiller load reference'!BB3 -> 158.6 | AB5: =AA5*Table1343[[#This Row],[Total Operating Hours]] -> 158.6 | AC5: ='[1]YVAM chiller load reference'!DH3 -> 0 | AD5: =AC5*Table1343[[#This Row],[Total Operating Hours]] -> 0 | AE5: ='[1]YVAM chiller load reference'!BI3 -> 139 | AF5: =AE5*Table1343[[#This Row],[Total Operating Hours]] -> 139 | AG5: ='[1]YVAM chiller load reference'!BP3 -> 146.2 | AH5: =AG5*Table1343[[#This Row],[Total Operating Hours]] -> 146.2
A6: 105 - 110 | B6: =B7+5 -> 107.5 | C6: 41.944444 | D6: 24 | E6: ='[1]YVAM chiller load reference'!D4 -> 341.1 | F6: =E6*Table1343[[#This Row],[Total Operating Hours]] -> 8186.4 | G6: ='[1]YVAM chiller load reference'!L4 -> 313.7 | H6: =G6*Table1343[[#This Row],[Total Operating Hours]] -> 7528.8 | I6: ='[1]YVAM chiller load reference'!S4 -> 277.6 | J6: =I6*Table1343[[#This Row],[Total Operating Hours]] -> 6662.4 | K6: ='[1]YVAM chiller load reference'!Z4 -> 244.5 | L6: =K6*Table1343[[#This Row],[Total Operating Hours]] -> 5868 | M6: ='[1]YVAM chiller load reference'!BD4 -> 237.5 | N6: =M6*Table1343[[#This Row],[Total Operating Hours]] -> 5700 | O6: ='[1]YVAM chiller load reference'!AG4 -> 213.9 | P6: =O6*Table1343[[#This Row],[Total Operating Hours]] -> 5133.6 | Q6: ='[1]YVAM chiller load reference'!BR4 -> 215.5 | R6: =Q6*Table1343[[#This Row],[Total Operating Hours]] -> 5172 | S6: ='[1]YVAM chiller load reference'!AN4 -> 185.7 | T6: =S6*Table1343[[#This Row],[Total Operating Hours]] -> 4456.8 | U6: ='[1]YVAM chiller load reference'!CF4 -> 0 | V6: =U6*Table1343[[#This Row],[Total Operating Hours]] -> 0 | W6: ='[1]YVAM chiller load reference'!AU4 -> 161.4 | X6: =W6*Table1343[[#This Row],[Total Operating Hours]] -> 3873.6 | Y6: ='[1]YVAM chiller load reference'!CT4 -> 0 | Z6: =Y6*Table1343[[#This Row],[Total Operating Hours]] -> 0 | AA6: ='[1]YVAM chiller load reference'!BB4 -> 142.3 | AB6: =AA6*Table1343[[#This Row],[Total Operating Hours]] -> 3415.2 | AC6: ='[1]YVAM chiller load reference'!DH4 -> 0 | AD6: =AC6*Table1343[[#This Row],[Total Operating Hours]] -> 0 | AE6: ='[1]YVAM chiller load reference'!BI4 -> 123 | AF6: =AE6*Table1343[[#This Row],[Total Operating Hours]] -> 2952 | AG6: ='[1]YVAM chiller load reference'!BP4 -> 119.5 | AH6: =AG6*Table1343[[#This Row],[Total Operating Hours]] -> 2868
A7: 100 - 105 | B7: =B8+5 -> 102.5 | C7: 39.166667 | D7: 118 | E7: ='[1]YVAM chiller load reference'!D5 -> 305.4 | F7: =E7*Table1343[[#This Row],[Total Operating Hours]] -> 36037.2 | G7: ='[1]YVAM chiller load reference'!L5 -> 280.4 | H7: =G7*Table1343[[#This Row],[Total Operating Hours]] -> 33087.2 | I7: ='[1]YVAM chiller load reference'!S5 -> 246.9 | J7: =I7*Table1343[[#This Row],[Total Operating Hours]] -> 29134.2 | K7: ='[1]YVAM chiller load reference'!Z5 -> 216.7 | L7: =K7*Table1343[[#This Row],[Total Operating Hours]] -> 25570.6 | M7: ='[1]YVAM chiller load reference'!BD5 -> 214.5 | N7: =M7*Table1343[[#This Row],[Total Operating Hours]] -> 25311 | O7: ='[1]YVAM chiller load reference'!AG5 -> 190 | P7: =O7*Table1343[[#This Row],[Total Operating Hours]] -> 22420 | Q7: ='[1]YVAM chiller load reference'!BR5 -> 196.5 | R7: =Q7*Table1343[[#This Row],[Total Operating Hours]] -> 23187 | S7: ='[1]YVAM chiller load reference'!AN5 -> 164.7 | T7: =S7*Table1343[[#This Row],[Total Operating Hours]] -> 19434.6 | U7: ='[1]YVAM chiller load reference'!CF5 -> 0 | V7: =U7*Table1343[[#This Row],[Total Operating Hours]] -> 0 | W7: ='[1]YVAM chiller load reference'!AU5 -> 142.4 | X7: =W7*Table1343[[#This Row],[Total Operating Hours]] -> 16803.2 | Y7: ='[1]YVAM chiller load reference'!CT5 -> 0 | Z7: =Y7*Table1343[[#This Row],[Total Operating Hours]] -> 0 | AA7: ='[1]YVAM chiller load reference'!BB5 -> 123.2 | AB7: =AA7*Table1343[[#This Row],[Total Operating Hours]] -> 14537.6 | AC7: ='[1]YVAM chiller load reference'!DH5 -> 0 | AD7: =AC7*Table1343[[#This Row],[Total Operating Hours]] -> 0 | AE7: ='[1]YVAM chiller load reference'!BI5 -> 109.6 | AF7: =AE7*Table1343[[#This Row],[Total Operating Hours]] -> 12932.8 | AG7: ='[1]YVAM chiller load reference'!BP5 -> 103.9 | AH7: =AG7*Table1343[[#This Row],[Total Operating Hours]] -> 12260.2
A8: 95 - 100 | B8: 97.5 | C8: 36.388889 | D8: 283 | E8: ='[1]YVAM chiller load reference'!D6 -> 273.2 | F8: =E8*Table1343[[#This Row],[Total Operating Hours]] -> 77315.6 | G8: ='[1]YVAM chiller load reference'!L6 -> 249.9 | H8: =G8*Table1343[[#This Row],[Total Operating Hours]] -> 70721.7 | I8: ='[1]YVAM chiller load reference'!S6 -> 220.7 | J8: =I8*Table1343[[#This Row],[Total Operating Hours]] -> 62458.1 | K8: ='[1]YVAM chiller load reference'!Z6 -> 192.6 | L8: =K8*Table1343[[#This Row],[Total Operating Hours]] -> 54505.8 | M8: ='[1]YVAM chiller load reference'!BD6 -> 189.5 | N8: =M8*Table1343[[#This Row],[Total Operating Hours]] -> 53628.5 | O8: ='[1]YVAM chiller load reference'!AG6 -> 166.5 | P8: =O8*Table1343[[#This Row],[Total Operating Hours]] -> 47119.5 | Q8: ='[1]YVAM chiller load reference'!BR6 -> 179.5 | R8: =Q8*Table1343[[#This Row],[Total Operating Hours]] -> 50798.5 | S8: ='[1]YVAM chiller load reference'!AN6 -> 142.6 | T8: =S8*Table1343[[#This Row],[Total Operating Hours]] -> 40355.8 | U8: ='[1]YVAM chiller load reference'!CF6 -> 0 | V8: =U8*Table1343[[#This Row],[Total Operating Hours]] -> 0 | W8: ='[1]YVAM chiller load reference'!AU6 -> 121.2 | X8: =W8*Table1343[[#This Row],[Total Operating Hours]] -> 34299.6 | Y8: ='[1]YVAM chiller load reference'!CT6 -> 0 | Z8: =Y8*Table1343[[#This Row],[Total Operating Hours]] -> 0 | AA8: ='[1]YVAM chiller load reference'!BB6 -> 101.2 | AB8: =AA8*Table1343[[#This Row],[Total Operating Hours]] -> 28639.6 | AC8: ='[1]YVAM chiller load reference'!DH6 -> 0 | AD8: =AC8*Table1343[[#This Row],[Total Operating Hours]] -> 0 | AE8: ='[1]YVAM chiller load reference'!BI6 -> 93.83 | AF8: =AE8*Table1343[[#This Row],[Total Operating Hours]] -> 26553.89 | AG8: ='[1]YVAM chiller load reference'!BP6 -> 90.71 | AH8: =AG8*Table1343[[#This Row],[Total Operating Hours]] -> 25670.93
A9: 90 - 95 | B9: =B8-5 -> 92.5 | C9: 33.611111 | D9: 320 | E9: ='[1]YVAM chiller load reference'!D7 -> 254 | F9: =E9*Table1343[[#This Row],[Total Operating Hours]] -> 81280 | G9: ='[1]YVAM chiller load reference'!L7 -> 231.4 | H9: =G9*Table1343[[#This Row],[Total Operating Hours]] -> 74048 | I9: ='[1]YVAM chiller load reference'!S7 -> 202.7 | J9: =I9*Table1343[[#This Row],[Total Operating Hours]] -> 64864 | K9: ='[1]YVAM chiller load reference'!Z7 -> 175.5 | L9: =K9*Table1343[[#This Row],[Total Operating Hours]] -> 56160 | M9: ='[1]YVAM chiller load reference'!BD7 -> 177.5 | N9: =M9*Table1343[[#This Row],[Total Operating Hours]] -> 56800 | O9: ='[1]YVAM chiller load reference'!AG7 -> 151.4 | P9: =O9*Table1343[[#This Row],[Total Operating Hours]] -> 48448 | Q9: ='[1]YVAM chiller load reference'!BR7 -> 167.5 | R9: =Q9*Table1343[[#This Row],[Total Operating Hours]] -> 53600 | S9: ='[1]YVAM chiller load reference'!AN7 -> 129.3 | T9: =S9*Table1343[[#This Row],[Total Operating Hours]] -> 41376 | U9: ='[1]YVAM chiller load reference'!CF7 -> 0 | V9: =U9*Table1343[[#This Row],[Total Operating Hours]] -> 0 | W9: ='[1]YVAM chiller load reference'!AU7 -> 109.8 | X9: =W9*Table1343[[#This Row],[Total Operating Hours]] -> 35136 | Y9: ='[1]YVAM chiller load reference'!CT7 -> 0 | Z9: =Y9*Table1343[[#This Row],[Total Operating Hours]] -> 0 | AA9: ='[1]YVAM chiller load reference'!BB7 -> 91.72 | AB9: =AA9*Table1343[[#This Row],[Total Operating Hours]] -> 29350.4 | AC9: ='[1]YVAM chiller load reference'!DH7 -> 0 | AD9: =AC9*Table1343[[#This Row],[Total Operating Hours]] -> 0 | AE9: ='[1]YVAM chiller load reference'!BI7 -> 80.73 | AF9: =AE9*Table1343[[#This Row],[Total Operating Hours]] -> 25833.6 | AG9: ='[1]YVAM chiller load reference'!BP7 -> 81.25 | AH9: =AG9*Table1343[[#This Row],[Total Operating Hours]] -> 26000
A10: 85 - 90 | B10: =B9-5 -> 87.5 | C10: 30.833333 | D10: 652 | E10: ='[1]YVAM chiller load reference'!D8 -> 226.3 | F10: =E10*Table1343[[#This Row],[Total Operating Hours]] -> 147547.6 | G10: ='[1]YVAM chiller load reference'!L8 -> 205 | H10: =G10*Table1343[[#This Row],[Total Operating Hours]] -> 133660 | I10: ='[1]YVAM chiller load reference'!S8 -> 178.7 | J10: =I10*Table1343[[#This Row],[Total Operating Hours]] -> 116512.4 | K10: ='[1]YVAM chiller load reference'!Z8 -> 154.7 | L10: =K10*Table1343[[#This Row],[Total Operating Hours]] -> 100864.4 | M10: ='[1]YVAM chiller load reference'!BD8 -> 160.5 | N10: =M10*Table1343[[#This Row],[Total Operating Hours]] -> 104646 | O10: ='[1]YVAM chiller load reference'!AG8 -> 131.9 | P10: =O10*Table1343[[#This Row],[Total Operating Hours]] -> 85998.8 | Q10: ='[1]YVAM chiller load reference'!BR8 -> 148.5 | R10: =Q10*Table1343[[#This Row],[Total Operating Hours]] -> 96822 | S10: ='[1]YVAM chiller load reference'!AN8 -> 111.5 | T10: =S10*Table1343[[#This Row],[Total Operating Hours]] -> 72698 | U10: ='[1]YVAM chiller load reference'!CF8 -> 0 | V10: =U10*Table1343[[#This Row],[Total Operating Hours]] -> 0 | W10: ='[1]YVAM chiller load reference'!AU8 -> 93.49 | X10: =W10*Table1343[[#This Row],[Total Operating Hours]] -> 60955.48 | Y10: ='[1]YVAM chiller load reference'!CT8 -> 0 | Z10: =Y10*Table1343[[#This Row],[Total Operating Hours]] -> 0 | AA10: ='[1]YVAM chiller load reference'!BB8 -> 77.81 | AB10: =AA10*Table1343[[#This Row],[Total Operating Hours]] -> 50732.12 | AC10: ='[1]YVAM chiller load reference'!DH8 -> 0 | AD10: =AC10*Table1343[[#This Row],[Total Operating Hours]] -> 0 | AE10: ='[1]YVAM chiller load reference'!BI8 -> 67.13 | AF10: =AE10*Table1343[[#This Row],[Total Operating Hours]] -> 43768.76 | AG10: ='[1]YVAM chiller load reference'!BP8 -> 66.35 | AH10: =AG10*Table1343[[#This Row],[Total Operating Hours]] -> 43260.2
A11: 80 - 85 | B11: =B10-5 -> 82.5 | C11: 28.055556 | D11: 802 | E11: ='[1]YVAM chiller load reference'!D9 -> 201.8 | F11: =E11*Table1343[[#This Row],[Total Operating Hours]] -> 161843.6 | G11: ='[1]YVAM chiller load reference'!L9 -> 181.4 | H11: =G11*Table1343[[#This Row],[Total Operating Hours]] -> 145482.8 | I11: ='[1]YVAM chiller load reference'!S9 -> 156.9 | J11: =I11*Table1343[[#This Row],[Total Operating Hours]] -> 125833.8 | K11: ='[1]YVAM chiller load reference'!Z9 -> 134.3 | L11: =K11*Table1343[[#This Row],[Total Operating Hours]] -> 107708.6 | M11: ='[1]YVAM chiller load reference'!BD9 -> 143.5 | N11: =M11*Table1343[[#This Row],[Total Operating Hours]] -> 115087 | O11: ='[1]YVAM chiller load reference'!AG9 -> 113.7 | P11: =O11*Table1343[[#This Row],[Total Operating Hours]] -> 91187.4 | Q11: ='[1]YVAM chiller load reference'!BR9 -> 132.5 | R11: =Q11*Table1343[[#This Row],[Total Operating Hours]] -> 106265 | S11: ='[1]YVAM chiller load reference'!AN9 -> 95.33 | T11: =S11*Table1343[[#This Row],[Total Operating Hours]] -> 76454.66 | U11: ='[1]YVAM chiller load reference'!CF9 -> 0 | V11: =U11*Table1343[[#This Row],[Total Operating Hours]] -> 0 | W11: ='[1]YVAM chiller load reference'!AU9 -> 78.95 | X11: =W11*Table1343[[#This Row],[Total Operating Hours]] -> 63317.9 | Y11: ='[1]YVAM chiller load reference'!CT9 -> 0 | Z11: =Y11*Table1343[[#This Row],[Total Operating Hours]] -> 0 | AA11: ='[1]YVAM chiller load reference'!BB9 -> 64.53 | AB11: =AA11*Table1343[[#This Row],[Total Operating Hours]] -> 51753.06 | AC11: ='[1]YVAM chiller load reference'!DH9 -> 0 | AD11: =AC11*Table1343[[#This Row],[Total Operating Hours]] -> 0 | AE11: ='[1]YVAM chiller load reference'!BI9 -> 53.21 | AF11: =AE11*Table1343[[#This Row],[Total Operating Hours]] -> 42674.42 | AG11: ='[1]YVAM chiller load reference'!BP9 -> 52.03 | AH11: =AG11*Table1343[[#This Row],[Total Operating Hours]] -> 41728.06
A12: 75 - 80 | B12: =B11-5 -> 77.5 | C12: 25.277778 | D12: 977 | E12: ='[1]YVAM chiller load reference'!D10 -> 178.2 | F12: =E12*Table1343[[#This Row],[Total Operating Hours]] -> 174101.4 | G12: ='[1]YVAM chiller load reference'!L10 -> 159.8 | H12: =G12*Table1343[[#This Row],[Total Operating Hours]] -> 156124.6 | I12: ='[1]YVAM chiller load reference'!S10 -> 137.3 | J12: =I12*Table1343[[#This Row],[Total Operating Hours]] -> 134142.1 | K12: ='[1]YVAM chiller load reference'!Z10 -> 116.5 | L12: =K12*Table1343[[#This Row],[Total Operating Hours]] -> 113820.5 | M12: ='[1]YVAM chiller load reference'!BD10 -> 129.5 | N12: =M12*Table1343[[#This Row],[Total Operating Hours]] -> 126521.5 | O12: ='[1]YVAM chiller load reference'!AG10 -> 97.59 | P12: =O12*Table1343[[#This Row],[Total Operating Hours]] -> 95345.43 | Q12: ='[1]YVAM chiller load reference'!BR10 -> 113.5 | R12: =Q12*Table1343[[#This Row],[Total Operating Hours]] -> 110889.5 | S12: ='[1]YVAM chiller load reference'!AN10 -> 80.81 | T12: =S12*Table1343[[#This Row],[Total Operating Hours]] -> 78951.37 | U12: ='[1]YVAM chiller load reference'!CF10 -> 0 | V12: =U12*Table1343[[#This Row],[Total Operating Hours]] -> 0 | W12: ='[1]YVAM chiller load reference'!AU10 -> 65.32 | X12: =W12*Table1343[[#This Row],[Total Operating Hours]] -> 63817.64 | Y12: ='[1]YVAM chiller load reference'!CT10 -> 0 | Z12: =Y12*Table1343[[#This Row],[Total Operating Hours]] -> 0 | AA12: ='[1]YVAM chiller load reference'!BB10 -> 51.95 | AB12: =AA12*Table1343[[#This Row],[Total Operating Hours]] -> 50755.15 | AC12: ='[1]YVAM chiller load reference'!DH10 -> 0 | AD12: =AC12*Table1343[[#This Row],[Total Operating Hours]] -> 0 | AE12: ='[1]YVAM chiller load reference'!BI10 -> 41.02 | AF12: =AE12*Table1343[[#This Row],[Total Operating Hours]] -> 40076.54 | AG12: ='[1]YVAM chiller load reference'!BP10 -> 37.18 | AH12: =AG12*Table1343[[#This Row],[Total Operating Hours]] -> 36324.86
A13: 70 - 75 | B13: =B12-5 -> 72.5 | C13: 22.5 | D13: 606 | E13: ='[1]YVAM chiller load reference'!D11 -> 164.1 | F13: =E13*Table1343[[#This Row],[Total Operating Hours]] -> 99444.6 | G13: ='[1]YVAM chiller load reference'!L11 -> 146.7 | H13: =G13*Table1343[[#This Row],[Total Operating Hours]] -> 88900.2 | I13: ='[1]YVAM chiller load reference'!S11 -> 125.3 | J13: =I13*Table1343[[#This Row],[Total Operating Hours]] -> 75931.8 | K13: ='[1]YVAM chiller load reference'!Z11 -> 105.6 | L13: =K13*Table1343[[#This Row],[Total Operating Hours]] -> 63993.6 | M13: ='[1]YVAM chiller load reference'!BD11 -> 122.5 | N13: =M13*Table1343[[#This Row],[Total Operating Hours]] -> 74235 | O13: ='[1]YVAM chiller load reference'!AG11 -> 87.8 | P13: =O13*Table1343[[#This Row],[Total Operating Hours]] -> 53206.8 | Q13: ='[1]YVAM chiller load reference'!BR11 -> 106.5 | R13: =Q13*Table1343[[#This Row],[Total Operating Hours]] -> 64539 | S13: ='[1]YVAM chiller load reference'!AN11 -> 72.01 | T13: =S13*Table1343[[#This Row],[Total Operating Hours]] -> 43638.06 | U13: ='[1]YVAM chiller load reference'!CF11 -> 0 | V13: =U13*Table1343[[#This Row],[Total Operating Hours]] -> 0 | W13: ='[1]YVAM chiller load reference'!AU11 -> 58.07 | X13: =W13*Table1343[[#This Row],[Total Operating Hours]] -> 35190.42 | Y13: ='[1]YVAM chiller load reference'!CT11 -> 0 | Z13: =Y13*Table1343[[#This Row],[Total Operating Hours]] -> 0 | AA13: ='[1]YVAM chiller load reference'!BB11 -> 45.86 | AB13: =AA13*Table1343[[#This Row],[Total Operating Hours]] -> 27791.16 | AC13: ='[1]YVAM chiller load reference'!DH11 -> 0 | AD13: =AC13*Table1343[[#This Row],[Total Operating Hours]] -> 0 | AE13: ='[1]YVAM chiller load reference'!BI11 -> 35.7 | AF13: =AE13*Table1343[[#This Row],[Total Operating Hours]] -> 21634.2 | AG13: ='[1]YVAM chiller load reference'!BP11 -> 31.22 | AH13: =AG13*Table1343[[#This Row],[Total Operating Hours]] -> 18919.32
A14: 65 - 70 | B14: =B13-5 -> 67.5 | C14: 19.722222 | D14: 901 | E14: ='[1]YVAM chiller load reference'!D12 -> 143.8 | F14: =E14*Table1343[[#This Row],[Total Operating Hours]] -> 129563.8 | G14: ='[1]YVAM chiller load reference'!L12 -> 127.8 | H14: =G14*Table1343[[#This Row],[Total Operating Hours]] -> 115147.8 | I14: ='[1]YVAM chiller load reference'!S12 -> 108.3 | J14: =I14*Table1343[[#This Row],[Total Operating Hours]] -> 97578.3 | K14: ='[1]YVAM chiller load reference'!Z12 -> 90.35 | L14: =K14*Table1343[[#This Row],[Total Operating Hours]] -> 81405.35 | M14: ='[1]YVAM chiller load reference'!BD12 -> 111.5 | N14: =M14*Table1343[[#This Row],[Total Operating Hours]] -> 100461.5 | O14: ='[1]YVAM chiller load reference'!AG12 -> 74.36 | P14: =O14*Table1343[[#This Row],[Total Operating Hours]] -> 66998.36 | Q14: ='[1]YVAM chiller load reference'!BR12 -> 98.5 | R14: =Q14*Table1343[[#This Row],[Total Operating Hours]] -> 88748.5 | S14: ='[1]YVAM chiller load reference'!AN12 -> 60.12 | T14: =S14*Table1343[[#This Row],[Total Operating Hours]] -> 54168.12 | U14: ='[1]YVAM chiller load reference'!CF12 -> 0 | V14: =U14*Table1343[[#This Row],[Total Operating Hours]] -> 0 | W14: ='[1]YVAM chiller load reference'!AU12 -> 47.93 | X14: =W14*Table1343[[#This Row],[Total Operating Hours]] -> 43184.93 | Y14: ='[1]YVAM chiller load reference'!CT12 -> 0 | Z14: =Y14*Table1343[[#This Row],[Total Operating Hours]] -> 0 | AA14: ='[1]YVAM chiller load reference'!BB12 -> 36.98 | AB14: =AA14*Table1343[[#This Row],[Total Operating Hours]] -> 33318.98 | AC14: ='[1]YVAM chiller load reference'!DH12 -> 0 | AD14: =AC14*Table1343[[#This Row],[Total Operating Hours]] -> 0 | AE14: ='[1]YVAM chiller load reference'!BI12 -> 27.75 | AF14: =AE14*Table1343[[#This Row],[Total Operating Hours]] -> 25002.75 | AG14: ='[1]YVAM chiller load reference'!BP12 -> 23.9 | AH14: =AG14*Table1343[[#This Row],[Total Operating Hours]] -> 21533.9
A15: 60 - 65 | B15: =B14-5 -> 62.5 | C15: 16.944444 | D15: 750 | E15: ='[1]YVAM chiller load reference'!D13 -> 124.9 | F15: =E15*Table1343[[#This Row],[Total Operating Hours]] -> 93675 | G15: ='[1]YVAM chiller load reference'!L13 -> 110.5 | H15: =G15*Table1343[[#This Row],[Total Operating Hours]] -> 82875 | I15: ='[1]YVAM chiller load reference'!S13 -> 92.69 | J15: =I15*Table1343[[#This Row],[Total Operating Hours]] -> 69517.5 | K15: ='[1]YVAM chiller load reference'!Z13 -> 76.4 | L15: =K15*Table1343[[#This Row],[Total Operating Hours]] -> 57300 | M15: ='[1]YVAM chiller load reference'!BD13 -> 102.5 | N15: =M15*Table1343[[#This Row],[Total Operating Hours]] -> 76875 | O15: ='[1]YVAM chiller load reference'!AG13 -> 62.02 | P15: =O15*Table1343[[#This Row],[Total Operating Hours]] -> 46515 | Q15: ='[1]YVAM chiller load reference'!BR13 -> 90.5 | R15: =Q15*Table1343[[#This Row],[Total Operating Hours]] -> 67875 | S15: ='[1]YVAM chiller load reference'!AN13 -> 49.46 | T15: =S15*Table1343[[#This Row],[Total Operating Hours]] -> 37095 | U15: ='[1]YVAM chiller load reference'!CF13 -> 0 | V15: =U15*Table1343[[#This Row],[Total Operating Hours]] -> 0 | W15: ='[1]YVAM chiller load reference'!AU13 -> 38.54 | X15: =W15*Table1343[[#This Row],[Total Operating Hours]] -> 28905 | Y15: ='[1]YVAM chiller load reference'!CT13 -> 0 | Z15: =Y15*Table1343[[#This Row],[Total Operating Hours]] -> 0 | AA15: ='[1]YVAM chiller load reference'!BB13 -> 29.28 | AB15: =AA15*Table1343[[#This Row],[Total Operating Hours]] -> 21960 | AC15: ='[1]YVAM chiller load reference'!DH13 -> 0 | AD15: =AC15*Table1343[[#This Row],[Total Operating Hours]] -> 0 | AE15: ='[1]YVAM chiller load reference'!BI13 -> 21.09 | AF15: =AE15*Table1343[[#This Row],[Total Operating Hours]] -> 15817.5 | AG15: ='[1]YVAM chiller load reference'!BP13 -> 17.58 | AH15: =AG15*Table1343[[#This Row],[Total Operating Hours]] -> 13185
A16: 55 - 60 | B16: =B15-5 -> 57.5 | C16: 14.166667 | D16: 730 | E16: ='[1]YVAM chiller load reference'!D14 -> 107.5 | F16: =E16*Table1343[[#This Row],[Total Operating Hours]] -> 78475 | G16: ='[1]YVAM chiller load reference'!L14 -> 94.44 | H16: =G16*Table1343[[#This Row],[Total Operating Hours]] -> 68941.2 | I16: ='[1]YVAM chiller load reference'!S14 -> 78.02 | J16: =I16*Table1343[[#This Row],[Total Operating Hours]] -> 56954.6 | K16: ='[1]YVAM chiller load reference'!Z14 -> 63.48 | L16: =K16*Table1343[[#This Row],[Total Operating Hours]] -> 46340.4 | M16: ='[1]YVAM chiller load reference'!BD14 -> 93.5 | N16: =M16*Table1343[[#This Row],[Total Operating Hours]] -> 68255 | O16: ='[1]YVAM chiller load reference'!AG14 -> 50.72 | P16: =O16*Table1343[[#This Row],[Total Operating Hours]] -> 37025.6 | Q16: ='[1]YVAM chiller load reference'!BR14 -> 87.5 | R16: =Q16*Table1343[[#This Row],[Total Operating Hours]] -> 63875 | S16: ='[1]YVAM chiller load reference'!AN14 -> 39.44 | T16: =S16*Table1343[[#This Row],[Total Operating Hours]] -> 28791.2 | U16: ='[1]YVAM chiller load reference'!CF14 -> 0 | V16: =U16*Table1343[[#This Row],[Total Operating Hours]] -> 0 | W16: ='[1]YVAM chiller load reference'!AU14 -> 29.72 | X16: =W16*Table1343[[#This Row],[Total Operating Hours]] -> 21695.6 | Y16: ='[1]YVAM chiller load reference'!CT14 -> 0 | Z16: =Y16*Table1343[[#This Row],[Total Operating Hours]] -> 0 | AA16: ='[1]YVAM chiller load reference'!BB14 -> 21.61 | AB16: =AA16*Table1343[[#This Row],[Total Operating Hours]] -> 15775.3 | AC16: ='[1]YVAM chiller load reference'!DH14 -> 0 | AD16: =AC16*Table1343[[#This Row],[Total Operating Hours]] -> 0 | AE16: ='[1]YVAM chiller load reference'!BI14 -> 15.76 | AF16: =AE16*Table1343[[#This Row],[Total Operating Hours]] -> 11504.8 | AG16: ='[1]YVAM chiller load reference'!BP14 -> 14.06 | AH16: =AG16*Table1343[[#This Row],[Total Operating Hours]] -> 10263.8
A17: 50 - 55 | B17: =B16-5 -> 52.5 | C17: 11.388889 | D17: 653 | E17: ='[1]YVAM chiller load reference'!D15 -> 92.56 | F17: =E17*Table1343[[#This Row],[Total Operating Hours]] -> 60441.68 | G17: ='[1]YVAM chiller load reference'!L15 -> 79.45 | H17: =G17*Table1343[[#This Row],[Total Operating Hours]] -> 51880.85 | I17: ='[1]YVAM chiller load reference'!S15 -> 64.74 | J17: =I17*Table1343[[#This Row],[Total Operating Hours]] -> 42275.22 | K17: ='[1]YVAM chiller load reference'!Z15 -> 51.59 | L17: =K17*Table1343[[#This Row],[Total Operating Hours]] -> 33688.27 | M17: ='[1]YVAM chiller load reference'!BD15 -> 91.5 | N17: =M17*Table1343[[#This Row],[Total Operating Hours]] -> 59749.5 | O17: ='[1]YVAM chiller load reference'!AG15 -> 39.76 | P17: =O17*Table1343[[#This Row],[Total Operating Hours]] -> 25963.28 | Q17: ='[1]YVAM chiller load reference'!BR15 -> 87.5 | R17: =Q17*Table1343[[#This Row],[Total Operating Hours]] -> 57137.5 | S17: ='[1]YVAM chiller load reference'!AN15 -> 30.14 | T17: =S17*Table1343[[#This Row],[Total Operating Hours]] -> 19681.42 | U17: ='[1]YVAM chiller load reference'!CF15 -> 0 | V17: =U17*Table1343[[#This Row],[Total Operating Hours]] -> 0 | W17: ='[1]YVAM chiller load reference'!AU15 -> 22.24 | X17: =W17*Table1343[[#This Row],[Total Operating Hours]] -> 14522.72 | Y17: ='[1]YVAM chiller load reference'!CT15 -> 0 | Z17: =Y17*Table1343[[#This Row],[Total Operating Hours]] -> 0 | AA17: ='[1]YVAM chiller load reference'!BB15 -> 17.55 | AB17: =AA17*Table1343[[#This Row],[Total Operating Hours]] -> 11460.15 | AC17: ='[1]YVAM chiller load reference'!DH15 -> 0 | AD17: =AC17*Table1343[[#This Row],[Total Operating Hours]] -> 0 | AE17: ='[1]YVAM chiller load reference'!BI15 -> 14.8 | AF17: =AE17*Table1343[[#This Row],[Total Operating Hours]] -> 9664.4 | AG17: ='[1]YVAM chiller load reference'!BP15 -> 13.2 | AH17: =AG17*Table1343[[#This Row],[Total Operating Hours]] -> 8619.6
A18: 45 - 50 | B18: =B17-5 -> 47.5 | C18: 8.6111111 | D18: 260 | E18: ='[1]YVAM chiller load reference'!D16 -> 83.85 | F18: =E18*Table1343[[#This Row],[Total Operating Hours]] -> 21801 | G18: ='[1]YVAM chiller load reference'!L16 -> 71.03 | H18: =G18*Table1343[[#This Row],[Total Operating Hours]] -> 18467.8 | I18: ='[1]YVAM chiller load reference'!S16 -> 57.14 | J18: =I18*Table1343[[#This Row],[Total Operating Hours]] -> 14856.4 | K18: ='[1]YVAM chiller load reference'!Z16 -> 44.17 | L18: =K18*Table1343[[#This Row],[Total Operating Hours]] -> 11484.2 | M18: ='[1]YVAM chiller load reference'!BD16 -> 91.5 | N18: =M18*Table1343[[#This Row],[Total Operating Hours]] -> 23790 | O18: ='[1]YVAM chiller load reference'!AG16 -> 34.62 | P18: =O18*Table1343[[#This Row],[Total Operating Hours]] -> 9001.2 | Q18: ='[1]YVAM chiller load reference'!BR16 -> 87.5 | R18: =Q18*Table1343[[#This Row],[Total Operating Hours]] -> 22750 | S18: ='[1]YVAM chiller load reference'!AN16 -> 26.67 | T18: =S18*Table1343[[#This Row],[Total Operating Hours]] -> 6934.2 | U18: ='[1]YVAM chiller load reference'!CF16 -> 0 | V18: =U18*Table1343[[#This Row],[Total Operating Hours]] -> 0 | W18: ='[1]YVAM chiller load reference'!AU16 -> 19.69 | X18: =W18*Table1343[[#This Row],[Total Operating Hours]] -> 5119.4 | Y18: ='[1]YVAM chiller load reference'!CT16 -> 0 | Z18: =Y18*Table1343[[#This Row],[Total Operating Hours]] -> 0 | AA18: ='[1]YVAM chiller load reference'!BB16 -> 16.82 | AB18: =AA18*Table1343[[#This Row],[Total Operating Hours]] -> 4373.2 | AC18: ='[1]YVAM chiller load reference'!DH16 -> 0 | AD18: =AC18*Table1343[[#This Row],[Total Operating Hours]] -> 0 | AE18: ='[1]YVAM chiller load reference'!BI16 -> 14.32 | AF18: =AE18*Table1343[[#This Row],[Total Operating Hours]] -> 3723.2 | AG18: ='[1]YVAM chiller load reference'!BP16 -> 13.06 | AH18: =AG18*Table1343[[#This Row],[Total Operating Hours]] -> 3395.6
A19: 40 - 45 | B19: =B18-5 -> 42.5 | C19: 5.8333333 | D19: 409 | E19: ='[1]YVAM chiller load reference'!D17 -> 73.2 | F19: =E19*Table1343[[#This Row],[Total Operating Hours]] -> 29938.8 | G19: ='[1]YVAM chiller load reference'!L17 -> 60.87 | H19: =G19*Table1343[[#This Row],[Total Operating Hours]] -> 24895.83 | I19: ='[1]YVAM chiller load reference'!S17 -> 48.31 | J19: =I19*Table1343[[#This Row],[Total Operating Hours]] -> 19758.79 | K19: ='[1]YVAM chiller load reference'!Z17 -> 36.73 | L19: =K19*Table1343[[#This Row],[Total Operating Hours]] -> 15022.57 | M19: ='[1]YVAM chiller load reference'!BD17 -> 91.5 | N19: =M19*Table1343[[#This Row],[Total Operating Hours]] -> 37423.5 | O19: ='[1]YVAM chiller load reference'!AG17 -> 28.62 | P19: =O19*Table1343[[#This Row],[Total Operating Hours]] -> 11705.58 | Q19: ='[1]YVAM chiller load reference'!BR17 -> 87.5 | R19: =Q19*Table1343[[#This Row],[Total Operating Hours]] -> 35787.5 | S19: ='[1]YVAM chiller load reference'!AN17 -> 22.36 | T19: =S19*Table1343[[#This Row],[Total Operating Hours]] -> 9145.24 | U19: ='[1]YVAM chiller load reference'!CF17 -> 0 | V19: =U19*Table1343[[#This Row],[Total Operating Hours]] -> 0 | W19: ='[1]YVAM chiller load reference'!AU17 -> 18.07 | X19: =W19*Table1343[[#This Row],[Total Operating Hours]] -> 7390.63 | Y19: ='[1]YVAM chiller load reference'!CT17 -> 0 | Z19: =Y19*Table1343[[#This Row],[Total Operating Hours]] -> 0 | AA19: ='[1]YVAM chiller load reference'!BB17 -> 16.26 | AB19: =AA19*Table1343[[#This Row],[Total Operating Hours]] -> 6650.34 | AC19: ='[1]YVAM chiller load reference'!DH17 -> 0 | AD19: =AC19*Table1343[[#This Row],[Total Operating Hours]] -> 0 | AE19: ='[1]YVAM chiller load reference'!BI17 -> 14.06 | AF19: =AE19*Table1343[[#This Row],[Total Operating Hours]] -> 5750.54 | AG19: ='[1]YVAM chiller load reference'!BP17 -> 12.92 | AH19: =AG19*Table1343[[#This Row],[Total Operating Hours]] -> 5284.28
A20: 35 - 40 | B20: =B19-5 -> 37.5 | C20: 3.0555556 | D20: 370 | E20: ='[1]YVAM chiller load reference'!D18 -> 66.47 | F20: =E20*Table1343[[#This Row],[Total Operating Hours]] -> 24593.9 | G20: ='[1]YVAM chiller load reference'!L18 -> 54.89 | H20: =G20*Table1343[[#This Row],[Total Operating Hours]] -> 20309.3 | I20: ='[1]YVAM chiller load reference'!S18 -> 41.71 | J20: =I20*Table1343[[#This Row],[Total Operating Hours]] -> 15432.7 | K20: ='[1]YVAM chiller load reference'!Z18 -> 32.1 | L20: =K20*Table1343[[#This Row],[Total Operating Hours]] -> 11877 | M20: ='[1]YVAM chiller load reference'!BD18 -> 91.5 | N20: =M20*Table1343[[#This Row],[Total Operating Hours]] -> 33855 | O20: ='[1]YVAM chiller load reference'!AG18 -> 25.37 | P20: =O20*Table1343[[#This Row],[Total Operating Hours]] -> 9386.9 | Q20: ='[1]YVAM chiller load reference'!BR18 -> 87.5 | R20: =Q20*Table1343[[#This Row],[Total Operating Hours]] -> 32375 | S20: ='[1]YVAM chiller load reference'!AN18 -> 20.45 | T20: =S20*Table1343[[#This Row],[Total Operating Hours]] -> 7566.5 | U20: ='[1]YVAM chiller load reference'!CF18 -> 0 | V20: =U20*Table1343[[#This Row],[Total Operating Hours]] -> 0 | W20: ='[1]YVAM chiller load reference'!AU18 -> 17.65 | X20: =W20*Table1343[[#This Row],[Total Operating Hours]] -> 6530.5 | Y20: ='[1]YVAM chiller load reference'!CT18 -> 0 | Z20: =Y20*Table1343[[#This Row],[Total Operating Hours]] -> 0 | AA20: ='[1]YVAM chiller load reference'!BB18 -> 16.33 | AB20: =AA20*Table1343[[#This Row],[Total Operating Hours]] -> 6042.1 | AC20: ='[1]YVAM chiller load reference'!DH18 -> 0 | AD20: =AC20*Table1343[[#This Row],[Total Operating Hours]] -> 0 | AE20: ='[1]YVAM chiller load reference'!BI18 -> 13.86 | AF20: =AE20*Table1343[[#This Row],[Total Operating Hours]] -> 5128.2 | AG20: ='[1]YVAM chiller load reference'!BP18 -> 12.94 | AH20: =AG20*Table1343[[#This Row],[Total Operating Hours]] -> 4787.8
... A23: 20 - 25 | B23: =B22-5 -> 22.5 | C23: -5.2777778 | D23: 91 | E23: ='[1]YVAM chiller load reference'!D21 -> 58.36 | F23: =E23*Table1343[[#This Row],[Total Operating Hours]] -> 5310.76 | G23: ='[1]YVAM chiller load reference'!L21 -> 47.34 | H23: =G23*Table1343[[#This Row],[Total Operating Hours]] -> 4307.94 | I23: ='[1]YVAM chiller load reference'!S21 -> 35.32 | J23: =I23*Table1343[[#This Row],[Total Operating Hours]] -> 3214.12 | K23: ='[1]YVAM chiller load reference'!Z21 -> 27.42 | L23: =K23*Table1343[[#This Row],[Total Operating Hours]] -> 2495.22 | M23: ='[1]YVAM chiller load reference'!BD21 -> 91.5 | N23: =M23*Table1343[[#This Row],[Total Operating Hours]] -> 8326.5 | O23: ='[1]YVAM chiller load reference'!AG21 -> 22.53 | P23: =O23*Table1343[[#This Row],[Total Operating Hours]] -> 2050.23 | Q23: ='[1]YVAM chiller load reference'!BR21 -> 87.5 | R23: =Q23*Table1343[[#This Row],[Total Operating Hours]] -> 7962.5 | S23: ='[1]YVAM chiller load reference'!AN21 -> 18.42 | T23: =S23*Table1343[[#This Row],[Total Operating Hours]] -> 1676.22 | U23: ='[1]YVAM chiller load reference'!CF21 -> 0 | V23: =U23*Table1343[[#This Row],[Total Operating Hours]] -> 0 | W23: ='[1]YVAM chiller load reference'!AU21 -> 16.48 | X23: =W23*Table1343[[#This Row],[Total Operating Hours]] -> 1499.68 | Y23: ='[1]YVAM chiller load reference'!CT21 -> 0 | Z23: =Y23*Table1343[[#This Row],[Total Operating Hours]] -> 0 | AA23: ='[1]YVAM chiller load reference'!BB21 -> 15.83 | AB23: =AA23*Table1343[[#This Row],[Total Operating Hours]] -> 1440.53 | AC23: ='[1]YVAM chiller load reference'!DH21 -> 0 | AD23: =AC23*Table1343[[#This Row],[Total Operating Hours]] -> 0 | AE23: ='[1]YVAM chiller load reference'!BI21 -> 13.93 | AF23: =AE23*Table1343[[#This Row],[Total Operating Hours]] -> 1267.63 | AG23: ='[1]YVAM chiller load reference'!BP21 -> 12.77 | AH23: =AG23*Table1343[[#This Row],[Total Operating Hours]] -> 1162.07
A24: 25 - 20 | B24: =B23-5 -> 17.5 | C24: -8.0555556 | D24: 140 | E24: 57.6 | F24: =E24*Table1343[[#This Row],[Total Operating Hours]] -> 8064 | G24: 46.48 | H24: =G24*Table1343[[#This Row],[Total Operating Hours]] -> 6507.2 | I24: 37.08 | J24: =I24*Table1343[[#This Row],[Total Operating Hours]] -> 5191.2 | K24: 28.39 | L24: =K24*Table1343[[#This Row],[Total Operating Hours]] -> 3974.6 | M24: ='[1]YVAM chiller load reference'!BD22 -> 0 | N24: =M24*Table1343[[#This Row],[Total Operating Hours]] -> 0 | O24: 22.97 | P24: =O24*Table1343[[#This Row],[Total Operating Hours]] -> 3215.8 | Q24: ='[1]YVAM chiller load reference'!BR22 -> 0 | R24: =Q24*Table1343[[#This Row],[Total Operating Hours]] -> 0 | S24: 18.54 | T24: =S24*Table1343[[#This Row],[Total Operating Hours]] -> 2595.6 | U24: ='[1]YVAM chiller load reference'!CF22 -> 0 | V24: =U24*Table1343[[#This Row],[Total Operating Hours]] -> 0 | W24: 16.46 | X24: =W24*Table1343[[#This Row],[Total Operating Hours]] -> 2304.4 | Y24: ='[1]YVAM chiller load reference'!CT22 -> 0 | Z24: =Y24*Table1343[[#This Row],[Total Operating Hours]] -> 0 | AA24: 15.57 | AB24: =AA24*Table1343[[#This Row],[Total Operating Hours]] -> 2179.8 | AC24: ='[1]YVAM chiller load reference'!DH22 -> 0 | AD24: =AC24*Table1343[[#This Row],[Total Operating Hours]] -> 0 | AE24: 13.93 | AF24: =AE24*Table1343[[#This Row],[Total Operating Hours]] -> 1950.2 | AG24: =AE24*0.91 -> 12.6763 | AH24: =AG24*Table1343[[#This Row],[Total Operating Hours]] -> 1774.682
A25: 20 - 15 | B25: =B24-5 -> 12.5 | C25: -10.833333 | D25: 56 | E25: 57.57 | F25: =E25*Table1342[[#This Row],[Total Operating Hours]] -> 3223.92 | G25: 47.01 | H25: =G25*Table1343[[#This Row],[Total Operating Hours]] -> 2632.56 | I25: 36.16 | J25: =I25*Table1343[[#This Row],[Total Operating Hours]] -> 2024.96 | K25: 27.91 | L25: =K25*Table1343[[#This Row],[Total Operating Hours]] -> 1562.96 | O25: 22.63 | P25: =O25*Table1343[[#This Row],[Total Operating Hours]] -> 1267.28 | S25: 18.44 | T25: =S25*Table1343[[#This Row],[Total Operating Hours]] -> 1032.64 | W25: 16.4 | X25: =W25*Table1343[[#This Row],[Total Operating Hours]] -> 918.4 | AA25: 15.62 | AB25: =AA25*Table1343[[#This Row],[Total Operating Hours]] -> 874.72 | AE25: 14.26 | AF25: =AE25*Table1343[[#This Row],[Total Operating Hours]] -> 798.56 | AG25: =AE25*0.91 -> 12.9766 | AH25: =AG25*Table1343[[#This Row],[Total Operating Hours]] -> 726.6896
A26: 15 - 10 | B26: =B25-5 -> 7.5 | C26: -13.611111 | D26: 10 | E26: 56.91 | F26: =E26*Table1342[[#This Row],[Total Operating Hours]] -> 569.1 | G26: 46.35 | H26: =G26*Table1343[[#This Row],[Total Operating Hours]] -> 463.5 | I26: 35.36 | J26: =I26*Table1343[[#This Row],[Total Operating Hours]] -> 353.6 | K26: 27.75 | L26: =K26*Table1343[[#This Row],[Total Operating Hours]] -> 277.5 | O26: 22.87 | P26: =O26*Table1343[[#This Row],[Total Operating Hours]] -> 228.7 | S26: 18.43 | T26: =S26*Table1343[[#This Row],[Total Operating Hours]] -> 184.3 | W26: 16.32 | X26: =W26*Table1343[[#This Row],[Total Operating Hours]] -> 163.2 | AA26: 15.59 | AB26: =AA26*Table1343[[#This Row],[Total Operating Hours]] -> 155.9 | AE26: 14.12 | AF26: =AE26*Table1343[[#This Row],[Total Operating Hours]] -> 141.2 | AG26: =AE26*0.91 -> 12.8492 | AH26: =AG26*Table1343[[#This Row],[Total Operating Hours]] -> 128.492
A27: 10 - 05 | B27: =B26-5 -> 2.5 | C27: -16.388889 | D27: 6 | E27: 57.16 | F27: =E27*Table1342[[#This Row],[Total Operating Hours]] -> 342.96 | G27: 45.77 | H27: =G27*Table1343[[#This Row],[Total Operating Hours]] -> 274.62 | I27: 36.8 | J27: =I27*Table1343[[#This Row],[Total Operating Hours]] -> 220.8 | K27: 28.46 | L27: =K27*Table1343[[#This Row],[Total Operating Hours]] -> 170.76 | O27: 23.07 | P27: =O27*Table1343[[#This Row],[Total Operating Hours]] -> 138.42 | S27: 18.19 | T27: =S27*Table1343[[#This Row],[Total Operating Hours]] -> 109.14 | W27: 16.39 | X27: =W27*Table1343[[#This Row],[Total Operating Hours]] -> 98.34 | AA27: 15.53 | AB27: =AA27*Table1343[[#This Row],[Total Operating Hours]] -> 93.18 | AE27: 14.2 | AF27: =AE27*Table1343[[#This Row],[Total Operating Hours]] -> 85.2 | AG27: =AE27*0.91 -> 12.922 | AH27: =AG27*Table1343[[#This Row],[Total Operating Hours]] -> 77.532
D28: =SUM(D5:D27) -> 8760 | F28: =SUBTOTAL(109,Table1343[Annual kW]) -> 1278915.4 | H28: =SUM(H5:H27) -> 1136458.9 | J28: =SUM(J5:J27) -> 965471.82 | L28: =SUM(L5:L27) -> 811472.07 | N28: =SUM(N5:N24) -> 1025916 | P28: =SUM(P5:P27) -> 676121.24 | R28: =SUM(R5:R24) -> 940612 | T28: =SUM(T5:T27) -> 557629.46 | V28: =SUM(V5:V24) -> 0 | X28: =SUM(X5:X27) -> 455949.89 | Z28: =SUM(Z5:Z24) -> 0 | AB28: =SUM(AB5:AB27) -> 371044.37 | AD28: =SUM(AD5:AD24) -> 0 | AF28: =SUM(AF5:AF27) -> 305871.69 | AH28: =SUM(AH5:AH27) -> 286003.52

Sheet YVAM chiller load reference 
D1: Input power
A2: 100 | B2: 46.1 | C2: 1300 | D2: 396.6 | E2: 3.278 | F2: 529.5 | I2: 100 | J2: 46.1 | K2: 1300 | L2: 415.4 | M2: 3.129 | N2: 560.5 | P2: 100 | Q2: 46.1 | R2: 1300 | S2: 415.4 | T2: 3.129 | U2: 560.5 | W2: 100 | X2: 46.1 | Y2: 1300 | Z2: 415.4 | AA2: 3.129 | AB2: 560.5 | AD2: 100 | AE2: 46.1 | AF2: 1300 | AG2: 415.4 | AH2: 3.129 | AI2: 560.5 | AK2: 100 | AL2: 46.1 | AM2: 1300 | AN2: 415.4 | AO2: 3.129 | AP2: 560.5 | AR2: 100 | AS2: 46.1 | AT2: 1300 | AU2: 415.4 | AV2: 3.129 | AW2: 560.5 | AY2: 100 | AZ2: 46.1 | BA2: 1300 | BB2: 415.4 | BC2: 3.129 | BD2: 560.5 | BF2: 100 | BG2: 46.1 | BH2: 1300 | BI2: 415.4 | BJ2: 3.129 | BK2: 560.5 | BM2: 100 | BN2: 46.1 | BO2: 1300 | BP2: 415.4 | BQ2: 3.129 | BR2: 560.5
A3: 100 | B3: 45 | C3: 1300 | D3: 380.4 | E3: 3.418 | F3: 508.5 | I3: 90 | J3: 45 | K3: 1170 | L3: 350.3 | M3: 3.34 | N3: 475.5 | P3: 80 | Q3: 45 | R3: 1040 | S3: 312 | T3: 3.334 | U3: 430.5 | W3: 70 | X3: 45 | Y3: 910.2 | Z3: 274.6 | AA3: 3.315 | AB3: 379.5 | AD3: 60 | AE3: 45 | AF3: 780 | AG3: 240.2 | AH3: 3.247 | AI3: 342.5 | AK3: 50 | AL3: 45 | AM3: 649.9 | AN3: 208.9 | AO3: 3.112 | AP3: 309.5 | AR3: 40 | AS3: 45 | AT3: 520.1 | AU3: 181.6 | AV3: 2.864 | AW3: 281.5 | AY3: 30 | AZ3: 45 | BA3: 390 | BB3: 158.6 | BC3: 2.459 | BD3: 259.5 | BF3: 20 | BG3: 45 | BH3: 260 | BI3: 139 | BJ3: 1.87 | BK3: 238.5 | BM3: 15 | BN3: 45 | BO3: 195 | BP3: 146.2 | BQ3: 1.334 | BR3: 240.5
A4: 100 | B4: 42 | C4: 1300 | D4: 341.1 | E4: 3.812 | F4: 460.5 | I4: 90 | J4: 42 | K4: 1170 | L4: 313.7 | M4: 3.729 | N4: 429.5 | P4: 80 | Q4: 42 | R4: 1040 | S4: 277.6 | T4: 3.747 | U4: 380.5 | W4: 70 | X4: 42 | Y4: 910.2 | Z4: 244.5 | AA4: 3.721 | AB4: 345.5 | AD4: 60 | AE4: 42 | AF4: 780 | AG4: 213.9 | AH4: 3.647 | AI4: 314.5 | AK4: 50 | AL4: 42 | AM4: 649.9 | AN4: 185.7 | AO4: 3.5 | AP4: 283.5 | AR4: 40 | AS4: 42 | AT4: 520.1 | AU4: 161.4 | AV4: 3.221 | AW4: 258.5 | AY4: 30 | AZ4: 42 | BA4: 390 | BB4: 142.3 | BC4: 2.741 | BD4: 237.5 | BF4: 20 | BG4: 42 | BH4: 260 | BI4: 123 | BJ4: 2.115 | BK4: 218.5 | BM4: 15 | BN4: 42 | BO4: 195 | BP4: 119.5 | BQ4: 1.632 | BR4: 215.5
A5: 100 | B5: 39 | C5: 1300 | D5: 305.4 | E5: 4.257 | F5: 417.5 | I5: 90 | J5: 39 | K5: 1170 | L5: 280.4 | M5: 4.172 | N5: 388.5 | P5: 80 | Q5: 39 | R5: 1040 | S5: 246.9 | T5: 4.212 | U5: 345.5 | W5: 70 | X5: 39 | Y5: 910.2 | Z5: 216.7 | AA5: 4.199 | AB5: 315.5 | AD5: 60 | AE5: 39 | AF5: 780 | AG5: 190 | AH5: 4.105 | AI5: 285.5 | AK5: 50 | AL5: 39 | AM5: 649.9 | AN5: 164.7 | AO5: 3.948 | AP5: 260.5 | AR5: 40 | AS5: 39 | AT5: 520.1 | AU5: 142.4 | AV5: 3.651 | AW5: 236.5 | AY5: 30 | AZ5: 39 | BA5: 390 | BB5: 123.2 | BC5: 3.166 | BD5: 214.5 | BF5: 20 | BG5: 39 | BH5: 260 | BI5: 109.6 | BJ5: 2.372 | BK5: 201.5 | BM5: 15 | BN5: 39 | BO5: 195 | BP5: 103.9 | BQ5: 1.876 | BR5: 196.5
A6: 100 | B6: 36 | C6: 1300 | D6: 273.2 | E6: 4.759 | F6: 373.5 | I6: 90 | J6: 36 | K6: 1170 | L6: 249.9 | M6: 4.682 | N6: 351.5 | P6: 80 | Q6: 36 | R6: 1040 | S6: 220.7 | T6: 4.712 | U6: 313.5 | W6: 70 | X6: 36 | Y6: 910.2 | Z6: 192.6 | AA6: 4.724 | AB6: 284.5 | AD6: 60 | AE6: 36 | AF6: 780 | AG6: 166.5 | AH6: 4.686 | AI6: 253.5 | AK6: 50 | AL6: 36 | AM6: 649.9 | AN6: 142.6 | AO6: 4.56 | AP6: 230.5 | AR6: 40 | AS6: 36 | AT6: 520.1 | AU6: 121.2 | AV6: 4.291 | AW6: 211.5 | AY6: 30 | AZ6: 36 | BA6: 390 | BB6: 101.2 | BC6: 3.855 | BD6: 189.5 | BF6: 20 | BG6: 36 | BH6: 260 | BI6: 93.83 | BJ6: 2.771 | BK6: 181.5 | BM6: 15 | BN6: 36 | BO6: 195 | BP6: 90.71 | BQ6: 2.15 | BR6: 179.5
A7: 100 | B7: 34 | C7: 1300 | D7: 254 | E7: 5.118 | F7: 350.5 | I7: 90 | J7: 34 | K7: 1170 | L7: 231.4 | M7: 5.056 | N7: 325.5 | P7: 80 | Q7: 34 | R7: 1040 | S7: 202.7 | T7: 5.13 | U7: 295.5 | W7: 70 | X7: 34 | Y7: 910.2 | Z7: 175.5 | AA7: 5.184 | AB7: 265.5 | AD7: 60 | AE7: 34 | AF7: 780 | AG7: 151.4 | AH7: 5.153 | AI7: 241.5 | AK7: 50 | AL7: 34 | AM7: 649.9 | AN7: 129.3 | AO7: 5.026 | AP7: 217.5 | AR7: 40 | AS7: 34 | AT7: 520.1 | AU7: 109.8 | AV7: 4.738 | AW7: 196.5 | AY7: 30 | AZ7: 34 | BA7: 390 | BB7: 91.72 | BC7: 4.252 | BD7: 177.5 | BF7: 20 | BG7: 34 | BH7: 260 | BI7: 80.73 | BJ7: 3.221 | BK7: 163.5 | BM7: 15 | BN7: 34 | BO7: 195 | BP7: 81.25 | BQ7: 2.401 | BR7: 167.5
A8: 100 | B8: 31 | C8: 1300 | D8: 226.3 | E8: 5.745 | F8: 320.5 | I8: 90 | J8: 31 | K8: 1170 | L8: 205 | M8: 5.708 | N8: 296.5 | P8: 80 | Q8: 31 | R8: 1040 | S8: 178.7 | T8: 5.821 | U8: 265.5 | W8: 70 | X8: 31 | Y8: 910.2 | Z8: 154.7 | AA8: 5.883 | AB8: 240.5 | AD8: 60 | AE8: 31 | AF8: 780 | AG8: 131.9 | AH8: 5.915 | AI8: 216.5 | AK8: 50 | AL8: 31 | AM8: 649.9 | AN8: 111.5 | AO8: 5.832 | AP8: 196.5 | AR8: 40 | AS8: 31 | AT8: 520.1 | AU8: 93.49 | AV8: 5.562 | AW8: 176.5 | AY8: 30 | AZ8: 31 | BA8: 390 | BB8: 77.81 | BC8: 5.012 | BD8: 160.5 | BF8: 20 | BG8: 31 | BH8: 260 | BI8: 67.13 | BJ8: 3.873 | BK8: 149.5 | BM8: 15 | BN8: 31 | BO8: 195 | BP8: 66.35 | BQ8: 2.938 | BR8: 148.5
A9: 100 | B9: 28 | C9: 1300 | D9: 201.8 | E9: 6.441 | F9: 290.5 | I9: 90 | J9: 28 | K9: 1170 | L9: 181.4 | M9: 6.45 | N9: 267.5 | P9: 80 | Q9: 28 | R9: 1040 | S9: 156.9 | T9: 6.63 | U9: 242.5 | W9: 70 | X9: 28 | Y9: 910.2 | Z9: 134.3 | AA9: 6.775 | AB9: 218.5 | AD9: 60 | AE9: 28 | AF9: 780 | AG9: 113.7 | AH9: 6.86 | AI9: 195.5 | AK9: 50 | AL9: 28 | AM9: 649.9 | AN9: 95.33 | AO9: 6.819 | AP9: 176.5 | AR9: 40 | AS9: 28 | AT9: 520.1 | AU9: 78.95 | AV9: 6.586 | AW9: 158.5 | AY9: 30 | AZ9: 28 | BA9: 390 | BB9: 64.53 | BC9: 6.044 | BD9: 143.5 | BF9: 20 | BG9: 28 | BH9: 260 | BI9: 53.21 | BJ9: 4.887 | BK9: 131.5 | BM9: 15 | BN9: 28 | BO9: 195 | BP9: 52.03 | BQ9: 3.748 | BR9: 132.5
A10: 100 | B10: 25 | C10: 1300 | D10: 178.2 | E10: 7.295 | F10: 265.5 | I10: 90 | J10: 25 | K10: 1170 | L10: 159.8 | M10: 7.323 | N10: 244.5 | P10: 80 | Q10: 25 | R10: 1040 | S10: 137.3 | T10: 7.576 | U10: 220.5 | W10: 70 | X10: 25 | Y10: 910.2 | Z10: 116.5 | AA10: 7.809 | AB10: 196.5 | AD10: 60 | AE10: 25 | AF10: 780 | AG10: 97.59 | AH10: 7.993 | AI10: 177.5 | AK10: 50 | AL10: 25 | AM10: 649.9 | AN10: 80.81 | AO10: 8.044 | AP10: 158.5 | AR10: 40 | AS10: 25 | AT10: 520.1 | AU10: 65.32 | AV10: 7.961 | AW10: 143.5 | AY10: 30 | AZ10: 25 | BA10: 390 | BB10: 51.95 | BC10: 7.509 | BD10: 129.5 | BF10: 20 | BG10: 25 | BH10: 260 | BI10: 41.02 | BJ10: 6.338 | BK10: 118.5 | BM10: 15 | BN10: 25 | BO10: 195 | BP10: 37.18 | BQ10: 5.245 | BR10: 113.5
A11: 100 | B11: 23 | C11: 1300 | D11: 164.1 | E11: 7.923 | F11: 247.5 | I11: 90 | J11: 23 | K11: 1170 | L11: 146.7 | M11: 7.977 | N11: 227.5 | P11: 80 | Q11: 23 | R11: 1040 | S11: 125.3 | T11: 8.301 | U11: 205.5 | W11: 70 | X11: 23 | Y11: 910.2 | Z11: 105.6 | AA11: 8.618 | AB11: 185.5 | AD11: 60 | AE11: 23 | AF11: 780 | AG11: 87.8 | AH11: 8.884 | AI11: 164.5 | AK11: 50 | AL11: 23 | AM11: 649.9 | AN11: 72.01 | AO11: 9.027 | AP11: 148.5 | AR11: 40 | AS11: 23 | AT11: 520.1 | AU11: 58.07 | AV11: 8.956 | AW11: 134.5 | AY11: 30 | AZ11: 23 | BA11: 390 | BB11: 45.86 | BC11: 8.505 | BD11: 122.5 | BF11: 20 | BG11: 23 | BH11: 260 | BI11: 35.7 | BJ11: 7.283 | BK11: 111.5 | BM11: 15 | BN11: 23 | BO11: 195 | BP11: 31.22 | BQ11: 6.247 | BR11: 106.5
A12: 100 | B12: 20 | C12: 1300 | D12: 143.8 | E12: 9.041 | F12: 223.5 | I12: 90 | J12: 20 | K12: 1170 | L12: 127.8 | M12: 9.154 | N12: 206.5 | P12: 80 | Q12: 20 | R12: 1040 | S12: 108.3 | T12: 9.607 | U12: 186.5 | W12: 70 | X12: 20 | Y12: 910.2 | Z12: 90.35 | AA12: 10.07 | AB12: 166.5 | AD12: 60 | AE12: 20 | AF12: 780 | AG12: 74.36 | AH12: 10.49 | AI12: 149.5 | AK12: 50 | AL12: 20 | AM12: 649.9 | AN12: 60.12 | AO12: 10.81 | AP12: 135.5 | AR12: 40 | AS12: 20 | AT12: 520.1 | AU12: 47.93 | AV12: 10.85 | AW12: 122.5 | AY12: 30 | AZ12: 20 | BA12: 390 | BB12: 36.98 | BC12: 10.55 | BD12: 111.5 | BF12: 20 | BG12: 20 | BH12: 260 | BI12: 27.75 | BJ12: 9.371 | BK12: 101.5 | BM12: 15 | BN12: 20 | BO12: 195 | BP12: 23.9 | BQ12: 8.16 | BR12: 98.5
A13: 100 | B13: 17 | C13: 1300 | D13: 124.9 | E13: 10.41 | F13: 201.5 | I13: 90 | J13: 17 | K13: 1170 | L13: 110.5 | M13: 10.59 | N13: 185.5 | P13: 80 | Q13: 17 | R13: 1040 | S13: 92.69 | T13: 11.22 | U13: 166.5 | W13: 70 | X13: 17 | Y13: 910.2 | Z13: 76.4 | AA13: 11.91 | AB13: 150.5 | AD13: 60 | AE13: 17 | AF13: 780 | AG13: 62.02 | AH13: 12.58 | AI13: 135.5 | AK13: 50 | AL13: 17 | AM13: 649.9 | AN13: 49.46 | AO13: 13.14 | AP13: 122.5 | AR13: 40 | AS13: 17 | AT13: 520.1 | AU13: 38.54 | AV13: 13.49 | AW13: 111.5 | AY13: 30 | AZ13: 17 | BA13: 390 | BB13: 29.28 | BC13: 13.32 | BD13: 102.5 | BF13: 20 | BG13: 17 | BH13: 260 | BI13: 21.09 | BJ13: 12.33 | BK13: 93.5 | BM13: 15 | BN13: 17 | BO13: 195 | BP13: 17.58 | BQ13: 11.09 | BR13: 90.5
... A21: 100 | B21: -5 | C21: 1300 | D21: 58.36 | E21: 22.27 | F21: 142.5 | I21: 90 | J21: -5 | K21: 1170 | L21: 47.34 | M21: 24.72 | N21: 128.5 | P21: 80 | Q21: -5 | R21: 1040 | S21: 35.32 | T21: 29.46 | U21: 114.5 | W21: 70 | X21: -5 | Y21: 910.2 | Z21: 27.42 | AA21: 33.18 | AB21: 104.5 | AD21: 60 | AE21: -5 | AF21: 780 | AG21: 22.53 | AH21: 34.62 | AI21: 98.5 | AK21: 50 | AL21: -5 | AM21: 649.9 | AN21: 18.42 | AO21: 35.29 | AP21: 93.5 | AR21: 40 | AS21: -5 | AT21: 520.1 | AU21: 16.48 | AV21: 31.57 | AW21: 91.5 | AY21: 30 | AZ21: -5 | BA21: 390 | BB21: 15.83 | BC21: 24.63 | BD21: 91.5 | BF21: 20 | BG21: -5 | BH21: 260 | BI21: 13.93 | BJ21: 18.67 | BK21: 88.5 | BM21: 15 | BN21: -5 | BO21: 195 | BP21: 12.77 | BQ21: 15.27 | BR21: 87.5

Sheet YVAM Annual Estimate @33-25
A2: YVAM1500--1300 KW@33C/25C Texas
E3: 1 | G3: 0.9 | I3: 0.8 | K3: 0.7 | M3: 0.65 | O3: 0.6 | Q3: 0.5 | S3: 0.4 | U3: 0.3 | W3: 0.25 | Y3: 0.2 | AA3: 0.15
A4: Bin Temp [F] | B4: Average Ambient[F] | C4: Average Ambient[C] | D4: Total Operating Hours | E4: kW | F4: Annual kW | G4: kW | H4: Annual kWh | I4: kW | J4: Annual kWh | K4: kW | L4: Annual kWh | M4: kW | N4: Annual kWh | O4: kW | P4: Annual kWh | Q4: kW | R4: Annual kWh | S4: kW | T4: Annual kWh | U4: kW | V4: Annual kWh | W4: kW | X4: Annual kWh | Y4: kW | Z4: Annual kWh | AA4: kW | AB4: Annual kWh
A5: 110 - 115 | B5: =B6+5 -> 112.5 | C5: =(Table1342[[#This Row],[Average Ambient'[F']]]-32)/1.8 -> 44.722222 | D5: 1 | E5: ='YVAM chiller load reference'!D3 -> 289.4 | F5: =E5*Table1342[[#This Row],[Total Operating Hours]] -> 289.4 | G5: ='YVAM chiller load reference'!L3 -> 259.1 | H5: =G5*Table1342[[#This Row],[Total Operating Hours]] -> 259.1 | I5: ='YVAM chiller load reference'!S3 -> 230.1 | J5: =I5*Table1342[[#This Row],[Total Operating Hours]] -> 230.1 | K5: ='YVAM chiller load reference'!Z3 -> 202.9 | L5: =K5*Table1342[[#This Row],[Total Operating Hours]] -> 202.9 | M5: ='YVAM chiller load reference'!BD3 -> 203.5 | N5: =M5*Table1342[[#This Row],[Total Operating Hours]] -> 203.5 | O5: ='YVAM chiller load reference'!AG3 -> 177 | P5: =O5*Table1342[[#This Row],[Total Operating Hours]] -> 177 | Q5: ='YVAM chiller load reference'!AN3 -> 153 | R5: =Q5*Table1342[[#This Row],[Total Operating Hours]] -> 153 | S5: ='YVAM chiller load reference'!AU3 -> 132 | T5: =S5*Table1342[[#This Row],[Total Operating Hours]] -> 132 | U5: ='YVAM chiller load reference'!BB3 -> 117.9 | V5: =U5*Table1342[[#This Row],[Total Operating Hours]] -> 117.9 | W5: ='YVAM chiller load reference'!DH3 -> 0 | X5: =W5*Table1342[[#This Row],[Total Operating Hours]] -> 0 | Y5: ='YVAM chiller load reference'!BI3 -> 114 | Z5: =Y5*Table1342[[#This Row],[Total Operating Hours]] -> 114 | AA5: ='YVAM chiller load reference'!BP3 -> 111.7 | AB5: =AA5*Table1342[[#This Row],[Total Operating Hours]] -> 111.7
A6: 105 - 110 | B6: =B7+5 -> 107.5 | C6: =(Table1342[[#This Row],[Average Ambient'[F']]]-32)/1.8 -> 41.944444 | D6: 24 | E6: ='YVAM chiller load reference'!D4 -> 256.9 | F6: =E6*Table1342[[#This Row],[Total Operating Hours]] -> 6165.6 | G6: ='YVAM chiller load reference'!L4 -> 226.8 | H6: =G6*Table1342[[#This Row],[Total Operating Hours]] -> 5443.2 | I6: ='YVAM chiller load reference'!S4 -> 200.8 | J6: =I6*Table1342[[#This Row],[Total Operating Hours]] -> 4819.2 | K6: ='YVAM chiller load reference'!Z4 -> 176.5 | L6: =K6*Table1342[[#This Row],[Total Operating Hours]] -> 4236 | M6: ='YVAM chiller load reference'!BD4 -> 185.5 | N6: =M6*Table1342[[#This Row],[Total Operating Hours]] -> 4452 | O6: ='YVAM chiller load reference'!AG4 -> 153.8 | P6: =O6*Table1342[[#This Row],[Total Operating Hours]] -> 3691.2 | Q6: ='YVAM chiller load reference'!AN4 -> 133.3 | R6: =Q6*Table1342[[#This Row],[Total Operating Hours]] -> 3199.2 | S6: ='YVAM chiller load reference'!AU4 -> 114.2 | T6: =S6*Table1342[[#This Row],[Total Operating Hours]] -> 2740.8 | U6: ='YVAM chiller load reference'!BB4 -> 98.73 | V6: =U6*Table1342[[#This Row],[Total Operating Hours]] -> 2369.52 | W6: ='YVAM chiller load reference'!DH4 -> 0 | X6: =W6*Table1342[[#This Row],[Total Operating Hours]] -> 0 | Y6: ='YVAM chiller load reference'!BI4 -> 93.41 | Z6: =Y6*Table1342[[#This Row],[Total Operating Hours]] -> 2241.84 | AA6: ='YVAM chiller load reference'!BP4 -> 95.76 | AB6: =AA6*Table1342[[#This Row],[Total Operating Hours]] -> 2298.24
A7: 100 - 105 | B7: =B8+5 -> 102.5 | C7: =(Table1342[[#This Row],[Average Ambient'[F']]]-32)/1.8 -> 39.166667 | D7: 118 | E7: ='YVAM chiller load reference'!D5 -> 226.4 | F7: =E7*Table1342[[#This Row],[Total Operating Hours]] -> 26715.2 | G7: ='YVAM chiller load reference'!L5 -> 200.4 | H7: =G7*Table1342[[#This Row],[Total Operating Hours]] -> 23647.2 | I7: ='YVAM chiller load reference'!S5 -> 175.8 | J7: =I7*Table1342[[#This Row],[Total Operating Hours]] -> 20744.4 | K7: ='YVAM chiller load reference'!Z5 -> 153.2 | L7: =K7*Table1342[[#This Row],[Total Operating Hours]] -> 18077.6 | M7: ='YVAM chiller load reference'!BD5 -> 165.5 | N7: =M7*Table1342[[#This Row],[Total Operating Hours]] -> 19529 | O7: ='YVAM chiller load reference'!AG5 -> 132.4 | P7: =O7*Table1342[[#This Row],[Total Operating Hours]] -> 15623.2 | Q7: ='YVAM chiller load reference'!AN5 -> 113.6 | R7: =Q7*Table1342[[#This Row],[Total Operating Hours]] -> 13404.8 | S7: ='YVAM chiller load reference'!AU5 -> 97.23 | T7: =S7*Table1342[[#This Row],[Total Operating Hours]] -> 11473.14 | U7: ='YVAM chiller load reference'!BB5 -> 83.01 | V7: =U7*Table1342[[#This Row],[Total Operating Hours]] -> 9795.18 | W7: ='YVAM chiller load reference'!DH5 -> 0 | X7: =W7*Table1342[[#This Row],[Total Operating Hours]] -> 0 | Y7: ='YVAM chiller load reference'!BI5 -> 76.03 | Z7: =Y7*Table1342[[#This Row],[Total Operating Hours]] -> 8971.54 | AA7: ='YVAM chiller load reference'!BP5 -> 76.9 | AB7: =AA7*Table1342[[#This Row],[Total Operating Hours]] -> 9074.2
A8: 95 - 100 | B8: 97.5 | C8: =(Table1342[[#This Row],[Average Ambient'[F']]]-32)/1.8 -> 36.388889 | D8: 283 | E8: ='YVAM chiller load reference'!D6 -> 199.4 | F8: =E8*Table1342[[#This Row],[Total Operating Hours]] -> 56430.2 | G8: ='YVAM chiller load reference'!L6 -> 175.1 | H8: =G8*Table1342[[#This Row],[Total Operating Hours]] -> 49553.3 | I8: ='YVAM chiller load reference'!S6 -> 152.7 | J8: =I8*Table1342[[#This Row],[Total Operating Hours]] -> 43214.1 | K8: ='YVAM chiller load reference'!Z6 -> 132 | L8: =K8*Table1342[[#This Row],[Total Operating Hours]] -> 37356 | M8: ='YVAM chiller load reference'!BD6 -> 145.5 | N8: =M8*Table1342[[#This Row],[Total Operating Hours]] -> 41176.5 | O8: ='YVAM chiller load reference'!AG6 -> 113.4 | P8: =O8*Table1342[[#This Row],[Total Operating Hours]] -> 32092.2 | Q8: ='YVAM chiller load reference'!AN6 -> 96.31 | R8: =Q8*Table1342[[#This Row],[Total Operating Hours]] -> 27255.73 | S8: ='YVAM chiller load reference'!AU6 -> 80.62 | T8: =S8*Table1342[[#This Row],[Total Operating Hours]] -> 22815.46 | U8: ='YVAM chiller load reference'!BB6 -> 67.65 | V8: =U8*Table1342[[#This Row],[Total Operating Hours]] -> 19144.95 | W8: ='YVAM chiller load reference'!DH6 -> 0 | X8: =W8*Table1342[[#This Row],[Total Operating Hours]] -> 0 | Y8: ='YVAM chiller load reference'!BI6 -> 58.84 | Z8: =Y8*Table1342[[#This Row],[Total Operating Hours]] -> 16651.72 | AA8: ='YVAM chiller load reference'!BP6 -> 60.63 | AB8: =AA8*Table1342[[#This Row],[Total Operating Hours]] -> 17158.29
A9: 90 - 95 | B9: =B8-5 -> 92.5 | C9: =(Table1342[[#This Row],[Average Ambient'[F']]]-32)/1.8 -> 33.611111 | D9: 320 | E9: ='YVAM chiller load reference'!D7 -> 182.9 | F9: =E9*Table1342[[#This Row],[Total Operating Hours]] -> 58528 | G9: ='YVAM chiller load reference'!L7 -> 159.9 | H9: =G9*Table1342[[#This Row],[Total Operating Hours]] -> 51168 | I9: ='YVAM chiller load reference'!S7 -> 138.8 | J9: =I9*Table1342[[#This Row],[Total Operating Hours]] -> 44416 | K9: ='YVAM chiller load reference'!Z7 -> 119.3 | L9: =K9*Table1342[[#This Row],[Total Operating Hours]] -> 38176 | M9: ='YVAM chiller load reference'!BD7 -> 135.5 | N9: =M9*Table1342[[#This Row],[Total Operating Hours]] -> 43360 | O9: ='YVAM chiller load reference'!AG7 -> 101.7 | P9: =O9*Table1342[[#This Row],[Total Operating Hours]] -> 32544 | Q9: ='YVAM chiller load reference'!AN7 -> 85.43 | R9: =Q9*Table1342[[#This Row],[Total Operating Hours]] -> 27337.6 | S9: ='YVAM chiller load reference'!AU7 -> 70.19 | T9: =S9*Table1342[[#This Row],[Total Operating Hours]] -> 22460.8 | U9: ='YVAM chiller load reference'!BB7 -> 57.46 | V9: =U9*Table1342[[#This Row],[Total Operating Hours]] -> 18387.2 | W9: ='YVAM chiller load reference'!DH7 -> 0 | X9: =W9*Table1342[[#This Row],[Total Operating Hours]] -> 0 | Y9: ='YVAM chiller load reference'!BI7 -> 48.49 | Z9: =Y9*Table1342[[#This Row],[Total Operating Hours]] -> 15516.8 | AA9: ='YVAM chiller load reference'!BP7 -> 47.09 | AB9: =AA9*Table1342[[#This Row],[Total Operating Hours]] -> 15068.8
A10: 85 - 90 | B10: =B9-5 -> 87.5 | C10: =(Table1342[[#This Row],[Average Ambient'[F']]]-32)/1.8 -> 30.833333 | D10: 652 | E10: ='YVAM chiller load reference'!D8 -> 159.9 | F10: =E10*Table1342[[#This Row],[Total Operating Hours]] -> 104254.8 | G10: ='YVAM chiller load reference'!L8 -> 138.8 | H10: =G10*Table1342[[#This Row],[Total Operating Hours]] -> 90497.6 | I10: ='YVAM chiller load reference'!S8 -> 119.6 | J10: =I10*Table1342[[#This Row],[Total Operating Hours]] -> 77979.2 | K10: ='YVAM chiller load reference'!Z8 -> 101.7 | L10: =K10*Table1342[[#This Row],[Total Operating Hours]] -> 66308.4 | M10: ='YVAM chiller load reference'!BD8 -> 124.5 | N10: =M10*Table1342[[#This Row],[Total Operating Hours]] -> 81174 | O10: ='YVAM chiller load reference'!AG8 -> 85.76 | P10: =O10*Table1342[[#This Row],[Total Operating Hours]] -> 55915.52 | Q10: ='YVAM chiller load reference'!AN8 -> 71.46 | R10: =Q10*Table1342[[#This Row],[Total Operating Hours]] -> 46591.92 | S10: ='YVAM chiller load reference'!AU8 -> 58.39 | T10: =S10*Table1342[[#This Row],[Total Operating Hours]] -> 38070.28 | U10: ='YVAM chiller load reference'!BB8 -> 47.15 | V10: =U10*Table1342[[#This Row],[Total Operating Hours]] -> 30741.8 | W10: ='YVAM chiller load reference'!DH8 -> 0 | X10: =W10*Table1342[[#This Row],[Total Operating Hours]] -> 0 | Y10: ='YVAM chiller load reference'!BI8 -> 37.56 | Z10: =Y10*Table1342[[#This Row],[Total Operating Hours]] -> 24489.12 | AA10: ='YVAM chiller load reference'!BP8 -> 33.87 | AB10: =AA10*Table1342[[#This Row],[Total Operating Hours]] -> 22083.24
A11: 80 - 85 | B11: =B10-5 -> 82.5 | C11: =(Table1342[[#This Row],[Average Ambient'[F']]]-32)/1.8 -> 28.055556 | D11: 802 | E11: ='YVAM chiller load reference'!D9 -> 138.7 | F11: =E11*Table1342[[#This Row],[Total Operating Hours]] -> 111237.4 | G11: ='YVAM chiller load reference'!L9 -> 119.3 | H11: =G11*Table1342[[#This Row],[Total Operating Hours]] -> 95678.6 | I11: ='YVAM chiller load reference'!S9 -> 102 | J11: =I11*Table1342[[#This Row],[Total Operating Hours]] -> 81804 | K11: ='YVAM chiller load reference'!Z9 -> 86.1 | L11: =K11*Table1342[[#This Row],[Total Operating Hours]] -> 69052.2 | M11: ='YVAM chiller load reference'!BD9 -> 111.5 | N11: =M11*Table1342[[#This Row],[Total Operating Hours]] -> 89423 | O11: ='YVAM chiller load reference'!AG9 -> 71.63 | P11: =O11*Table1342[[#This Row],[Total Operating Hours]] -> 57447.26 | Q11: ='YVAM chiller load reference'!AN9 -> 59.02 | R11: =Q11*Table1342[[#This Row],[Total Operating Hours]] -> 47334.04 | S11: ='YVAM chiller load reference'!AU9 -> 47.59 | T11: =S11*Table1342[[#This Row],[Total Operating Hours]] -> 38167.18 | U11: ='YVAM chiller load reference'!BB9 -> 37.39 | V11: =U11*Table1342[[#This Row],[Total Operating Hours]] -> 29986.78 | W11: ='YVAM chiller load reference'!DH9 -> 0 | X11: =W11*Table1342[[#This Row],[Total Operating Hours]] -> 0 | Y11: ='YVAM chiller load reference'!BI9 -> 28.52 | Z11: =Y11*Table1342[[#This Row],[Total Operating Hours]] -> 22873.04 | AA11: ='YVAM chiller load reference'!BP9 -> 24.84 | AB11: =AA11*Table1342[[#This Row],[Total Operating Hours]] -> 19921.68
A12: 75 - 80 | B12: =B11-5 -> 77.5 | C12: =(Table1342[[#This Row],[Average Ambient'[F']]]-32)/1.8 -> 25.277778 | D12: 977 | E12: ='YVAM chiller load reference'!D10 -> 119 | F12: =E12*Table1342[[#This Row],[Total Operating Hours]] -> 116263 | G12: ='YVAM chiller load reference'!L10 -> 101.6 | H12: =G12*Table1342[[#This Row],[Total Operating Hours]] -> 99263.2 | I12: ='YVAM chiller load reference'!S10 -> 85.89 | J12: =I12*Table1342[[#This Row],[Total Operating Hours]] -> 83914.53 | K12: ='YVAM chiller load reference'!Z10 -> 71.7 | L12: =K12*Table1342[[#This Row],[Total Operating Hours]] -> 70050.9 | M12: ='YVAM chiller load reference'!BD10 -> 100.5 | N12: =M12*Table1342[[#This Row],[Total Operating Hours]] -> 98188.5 | O12: ='YVAM chiller load reference'!AG10 -> 58.88 | P12: =O12*Table1342[[#This Row],[Total Operating Hours]] -> 57525.76 | Q12: ='YVAM chiller load reference'!AN10 -> 47.63 | R12: =Q12*Table1342[[#This Row],[Total Operating Hours]] -> 46534.51 | S12: ='YVAM chiller load reference'!AU10 -> 37.57 | T12: =S12*Table1342[[#This Row],[Total Operating Hours]] -> 36705.89 | U12: ='YVAM chiller load reference'!BB10 -> 28.9 | V12: =U12*Table1342[[#This Row],[Total Operating Hours]] -> 28235.3 | W12: ='YVAM chiller load reference'!DH10 -> 0 | X12: =W12*Table1342[[#This Row],[Total Operating Hours]] -> 0 | Y12: ='YVAM chiller load reference'!BI10 -> 21.11 | Z12: =Y12*Table1342[[#This Row],[Total Operating Hours]] -> 20624.47 | AA12: ='YVAM chiller load reference'!BP10 -> 17.74 | AB12: =AA12*Table1342[[#This Row],[Total Operating Hours]] -> 17331.98
